[0m00:11:39.229517 [debug] [MainThread]: Sending event: {'category': 'dbt', 'action': 'invocation', 'label': 'start', 'context': [<snowplow_tracker.self_describing_json.SelfDescribingJson object at 0x0000023F7A507EE0>, <snowplow_tracker.self_describing_json.SelfDescribingJson object at 0x0000023F7D03D2E0>, <snowplow_tracker.self_describing_json.SelfDescribingJson object at 0x0000023F7D03D250>]}


============================== 00:11:39.280529 | 8391a89a-15f4-47d1-bf7c-17b4ab00cfe9 ==============================
[0m00:11:39.280529 [info ] [MainThread]: Running with dbt=1.7.0
[0m00:11:39.282515 [debug] [MainThread]: running dbt with arguments {'printer_width': '80', 'indirect_selection': 'eager', 'write_json': 'True', 'log_cache_events': 'False', 'partial_parse': 'True', 'cache_selected_only': 'False', 'warn_error': 'None', 'fail_fast': 'False', 'debug': 'False', 'log_path': 'logs', 'version_check': 'True', 'profiles_dir': 'C:\\Users\\asus\\.dbt', 'use_colors': 'True', 'use_experimental_parser': 'False', 'no_print': 'None', 'quiet': 'False', 'log_format': 'default', 'invocation_command': 'dbt init', 'warn_error_options': 'WarnErrorOptions(include=[], exclude=[])', 'static_parser': 'True', 'target_path': 'None', 'introspect': 'True', 'send_anonymous_usage_stats': 'True'}
[0m00:12:10.531822 [debug] [MainThread]: Starter project path: C:\Users\asus\AppData\Local\pypoetry\Cache\virtualenvs\sales-product-data-dbt-i9QQrJJO-py3.9\lib\site-packages\dbt\include\starter_project
[0m00:12:10.588678 [info ] [MainThread]: 
Your new dbt project "sales_product_data_dbt" was created!

For more information on how to configure the profiles.yml file,
please consult the dbt documentation here:

  https://docs.getdbt.com/docs/configure-your-profile

One more thing:

Need help? Don't hesitate to reach out to us via GitHub issues or on Slack:

  https://community.getdbt.com/

Happy modeling!

[0m00:12:10.591677 [info ] [MainThread]: Setting up your profile.
[0m00:12:34.585145 [error] [MainThread]: Encountered an error:

[0m00:12:34.588134 [error] [MainThread]: Traceback (most recent call last):
  File "C:\Users\asus\AppData\Local\pypoetry\Cache\virtualenvs\sales-product-data-dbt-i9QQrJJO-py3.9\lib\site-packages\dbt\cli\requires.py", line 90, in wrapper
    result, success = func(*args, **kwargs)
  File "C:\Users\asus\AppData\Local\pypoetry\Cache\virtualenvs\sales-product-data-dbt-i9QQrJJO-py3.9\lib\site-packages\dbt\cli\requires.py", line 75, in wrapper
    return func(*args, **kwargs)
  File "C:\Users\asus\AppData\Local\pypoetry\Cache\virtualenvs\sales-product-data-dbt-i9QQrJJO-py3.9\lib\site-packages\dbt\cli\main.py", line 515, in init
    results = task.run()
  File "C:\Users\asus\AppData\Local\pypoetry\Cache\virtualenvs\sales-product-data-dbt-i9QQrJJO-py3.9\lib\site-packages\dbt\task\init.py", line 344, in run
    self.setup_profile(profile_name)
  File "C:\Users\asus\AppData\Local\pypoetry\Cache\virtualenvs\sales-product-data-dbt-i9QQrJJO-py3.9\lib\site-packages\dbt\task\init.py", line 264, in setup_profile
    self.create_profile_from_target(adapter, profile_name=profile_name)
  File "C:\Users\asus\AppData\Local\pypoetry\Cache\virtualenvs\sales-product-data-dbt-i9QQrJJO-py3.9\lib\site-packages\dbt\task\init.py", line 181, in create_profile_from_target
    self.create_profile_from_profile_template(profile_template, profile_name)
  File "C:\Users\asus\AppData\Local\pypoetry\Cache\virtualenvs\sales-product-data-dbt-i9QQrJJO-py3.9\lib\site-packages\dbt\task\init.py", line 165, in create_profile_from_profile_template
    target = self.generate_target_from_input(prompts, initial_target)
  File "C:\Users\asus\AppData\Local\pypoetry\Cache\virtualenvs\sales-product-data-dbt-i9QQrJJO-py3.9\lib\site-packages\dbt\task\init.py", line 118, in generate_target_from_input
    target = self.generate_target_from_input(
  File "C:\Users\asus\AppData\Local\pypoetry\Cache\virtualenvs\sales-product-data-dbt-i9QQrJJO-py3.9\lib\site-packages\dbt\task\init.py", line 131, in generate_target_from_input
    target[key] = click.prompt(
  File "C:\Users\asus\AppData\Local\pypoetry\Cache\virtualenvs\sales-product-data-dbt-i9QQrJJO-py3.9\lib\site-packages\click\termui.py", line 164, in prompt
    value = prompt_func(prompt)
  File "C:\Users\asus\AppData\Local\pypoetry\Cache\virtualenvs\sales-product-data-dbt-i9QQrJJO-py3.9\lib\site-packages\click\termui.py", line 147, in prompt_func
    raise Abort() from None
click.exceptions.Abort

[0m00:12:34.592129 [debug] [MainThread]: Command `dbt init` failed at 00:12:34.592129 after 55.37 seconds
[0m00:12:34.593127 [debug] [MainThread]: Sending event: {'category': 'dbt', 'action': 'invocation', 'label': 'end', 'context': [<snowplow_tracker.self_describing_json.SelfDescribingJson object at 0x0000023F7A507EE0>, <snowplow_tracker.self_describing_json.SelfDescribingJson object at 0x0000023F7E5121F0>, <snowplow_tracker.self_describing_json.SelfDescribingJson object at 0x0000023F7E512CA0>]}
[0m00:12:34.594125 [debug] [MainThread]: Flushing usage events
